{"success": true, "error": null, "issues": [{"title": "Dependence on predictable environment variable", "description": "In the function '_function_0xe9874106' the following predictable state variables are used to determine Ether recipient:\n- block.coinbase\n", "function": "_function_0xe9874106", "type": "Warning", "address": 1285, "debug": "", "filename": "<TEST_FILES>/weak_random.sol", "lineno": 47, "code": "winningAddress.transfer(prize)"}, {"title": "Ether send", "description": "In the function '_function_0xe9874106' a non-zero amount of Ether is sent to an address taken from storage slot 0There is a check on storage index 0. This storage slot can be written to by calling the function 'fallback'.\n\nThere is a check on storage index 10. This storage slot can be written to by calling the function 'fallback'.\nThere is a check on storage index 11. This storage slot can be written to by calling the function 'fallback'.", "function": "_function_0xe9874106", "type": "Warning", "address": 1285, "debug": "SOLVER OUTPUT:\ncallvalue: 0xb1a2bc2ec50000\ncalldata_WeakRandom_0: 0x6d3b4c700000000000000000000000000000000000000000000000000000000\ncalldatasize_WeakRandom: 0x4\nstorage_1: 0x32\n", "filename": "<TEST_FILES>/weak_random.sol", "lineno": 47, "code": "winningAddress.transfer(prize)"}, {"title": "Exception state", "description": "A reachable exception (opcode 0xfe) has been detected. This can be caused by type errors, division by zero, out-of-bounds array access, or assert violations. This is acceptable in most situations. Note however that assert() should only be used to check invariants. Use require() for regular input checking. ", "function": "fallback", "type": "Informational", "address": 356, "debug": "The exception is triggered under the following conditions:\n\ncallvalue: 0x215c4a82f200000\nstorage_1: 0x31\ncalldatasize_WeakRandom: 0x3\n", "filename": "<TEST_FILES>/weak_random.sol", "lineno": 11, "code": "prize / totalTickets"}, {"title": "Exception state", "description": "A reachable exception (opcode 0xfe) has been detected. This can be caused by type errors, division by zero, out-of-bounds array access, or assert violations. This is acceptable in most situations. Note however that assert() should only be used to check invariants. Use require() for regular input checking. ", "function": "_function_0xe9874106", "type": "Informational", "address": 146, "debug": "The exception is triggered under the following conditions:\n\ncallvalue: 0x2000000000000000000000000000000000000000000000068805cbe800000\nstorage_1: 0x31\ncalldata_WeakRandom_0: 0x600000000000000000000000000000000000000000000000000000000\ncalldatasize_WeakRandom: 0x4\n", "filename": "<TEST_FILES>/weak_random.sol", "lineno": 11, "code": "prize / totalTickets"}]}